Workbook

Sheet Trade Database
A1: TRADE LIFECYCLE OPERATIONS COMMAND CENTER
A2: IronHub Capital | T+1 Settlement Desk | India Markets | Equities | Fixed Income | Derivatives | Commodities
A4: Trade ID | B4: Trade Date | C4: Settlement Date | D4: Asset Class | E4: Product | F4: ISIN | G4: Currency | H4: Quantity | I4: Price | J4: Trade Value | K4: Broker | L4: Counterparty | M4: Lifecycle Stage | N4: Trade Status | O4: Failure Type | P4: Aging Days | Q4: Severity Score | R4: Risk Score | S4: RAG Status | T4: Settlement Risk | U4: Priority Rank
A5: TRD-001 | B5: 45688 | C5: 45689 | D5: Equity | E5: Tata Consultancy Services | F5: INE467B01029 | G5: INR | H5: 200 | I5: 3749.1 | J5: =H5*I5 -> 749820 | K5: HDFC Securities | L5: Nuvama Wealth | M5: S7 Settlement | N5: Settled | P5: =Config!$B$1-B5 -> 493 | Q5: =IFERROR(INDEX('Failure Reference'!$C$4:$C$9,MATCH(O5,'Failure Reference'!$A$4:$A$9,0)),0) -> 0 | R5: =IF(N5="Settled",0,Q5+P5*0.5+IFERROR(INDEX(Config!$B$4:$B$7,MATCH(D5,Config!$A$4:$A$7,0)),1)+IF(C5-Config!$B$1<=1,5,0)) -> 0 | S5: =IF(R5=0,"Green",IF(R5<10,"Amber","Red")) -> Green | T5: =IF(N5="Settled","None",IF(C5-Config!$B$1<=0,"Overdue",IF(C5-Config!$B$1<=1,"Critical",IF(C5-Config!$B$1<=3,"High","Low")))) -> None | U5: =IF(R5=0,"",RANK(R5,$R$5:$R$104,0))
A6: TRD-002 | B6: 45716 | C6: 45717 | D6: Equity | E6: Axis Bank Ltd | F6: INE238A01034 | G6: INR | H6: 200 | I6: 931.7 | J6: =H6*I6 -> 186340 | K6: HDFC Securities | L6: Axis Securities | M6: S7 Settlement | N6: Settled | P6: =Config!$B$1-B6 -> 465 | Q6: =IFERROR(INDEX('Failure Reference'!$C$4:$C$9,MATCH(O6,'Failure Reference'!$A$4:$A$9,0)),0) -> 0 | R6: =IF(N6="Settled",0,Q6+P6*0.5+IFERROR(INDEX(Config!$B$4:$B$7,MATCH(D6,Config!$A$4:$A$7,0)),1)+IF(C6-Config!$B$1<=1,5,0)) -> 0 | S6: =IF(R6=0,"Green",IF(R6<10,"Amber","Red")) -> Green | T6: =IF(N6="Settled","None",IF(C6-Config!$B$1<=0,"Overdue",IF(C6-Config!$B$1<=1,"Critical",IF(C6-Config!$B$1<=3,"High","Low")))) -> None | U6: =IF(R6=0,"",RANK(R6,$R$5:$R$104,0))
A7: TRD-003 | B7: 45675 | C7: 45676 | D7: Fixed Income | E7: 7.18% GOI 2033 | F7: IN002023Y123 | G7: INR | H7: 5000 | I7: 99.51 | J7: =H7*I7 -> 497550 | K7: Kotak Securities | L7: Sharekhan | M7: S5 Matching | N7: Break | O7: Matching Break | P7: =Config!$B$1-B7 -> 506 | Q7: =IFERROR(INDEX('Failure Reference'!$C$4:$C$9,MATCH(O7,'Failure Reference'!$A$4:$A$9,0)),0) -> 8 | R7: =IF(N7="Settled",0,Q7+P7*0.5+IFERROR(INDEX(Config!$B$4:$B$7,MATCH(D7,Config!$A$4:$A$7,0)),1)+IF(C7-Config!$B$1<=1,5,0)) -> 267.5 | S7: =IF(R7=0,"Green",IF(R7<10,"Amber","Red")) -> Red | T7: =IF(N7="Settled","None",IF(C7-Config!$B$1<=0,"Overdue",IF(C7-Config!$B$1<=1,"Critical",IF(C7-Config!$B$1<=3,"High","Low")))) -> Overdue | U7: =IF(R7=0,"",RANK(R7,$R$5:$R$104,0)) -> 2
A8: TRD-004 | B8: 45829 | C8: 45830 | D8: Fixed Income | E8: T-Bill 91D | F8: IN002024T001 | G8: INR | H8: 2000 | I8: 99.66 | J8: =H8*I8 -> 199320 | K8: Nuvama Wealth | L8: IIFL Securities | M8: S7 Settlement | N8: Settled | P8: =Config!$B$1-B8 -> 352 | Q8: =IFERROR(INDEX('Failure Reference'!$C$4:$C$9,MATCH(O8,'Failure Reference'!$A$4:$A$9,0)),0) -> 0 | R8: =IF(N8="Settled",0,Q8+P8*0.5+IFERROR(INDEX(Config!$B$4:$B$7,MATCH(D8,Config!$A$4:$A$7,0)),1)+IF(C8-Config!$B$1<=1,5,0)) -> 0 | S8: =IF(R8=0,"Green",IF(R8<10,"Amber","Red")) -> Green | T8: =IF(N8="Settled","None",IF(C8-Config!$B$1<=0,"Overdue",IF(C8-Config!$B$1<=1,"Critical",IF(C8-Config!$B$1<=3,"High","Low")))) -> None | U8: =IF(R8=0,"",RANK(R8,$R$5:$R$104,0))
A9: TRD-005 | B9: 45720 | C9: 45721 | D9: Equity | E9: Asian Paints Ltd | F9: INE021A01026 | G9: INR | H9: 500 | I9: 2978.87 | J9: =H9*I9 -> 1489435 | K9: Kotak Securities | L9: ICICI Securities | M9: S7 Settlement | N9: Settled | P9: =Config!$B$1-B9 -> 461 | Q9: =IFERROR(INDEX('Failure Reference'!$C$4:$C$9,MATCH(O9,'Failure Reference'!$A$4:$A$9,0)),0) -> 0 | R9: =IF(N9="Settled",0,Q9+P9*0.5+IFERROR(INDEX(Config!$B$4:$B$7,MATCH(D9,Config!$A$4:$A$7,0)),1)+IF(C9-Config!$B$1<=1,5,0)) -> 0 | S9: =IF(R9=0,"Green",IF(R9<10,"Amber","Red")) -> Green | T9: =IF(N9="Settled","None",IF(C9-Config!$B$1<=0,"Overdue",IF(C9-Config!$B$1<=1,"Critical",IF(C9-Config!$B$1<=3,"High","Low")))) -> None | U9: =IF(R9=0,"",RANK(R9,$R$5:$R$104,0))
A10: TRD-006 | B10: 45682 | C10: 45683 | D10: Fixed Income | E10: Tata Steel Corp Bond | F10: INE081A08123 | G10: INR | H10: 10000 | I10: 101.7 | J10: =H10*I10 -> 1017000 | K10: Angel One | L10: JM Financial | M10: S7 Settlement | N10: Settled | P10: =Config!$B$1-B10 -> 499 | Q10: =IFERROR(INDEX('Failure Reference'!$C$4:$C$9,MATCH(O10,'Failure Reference'!$A$4:$A$9,0)),0) -> 0 | R10: =IF(N10="Settled",0,Q10+P10*0.5+IFERROR(INDEX(Config!$B$4:$B$7,MATCH(D10,Config!$A$4:$A$7,0)),1)+IF(C10-Config!$B$1<=1,5,0)) -> 0 | S10: =IF(R10=0,"Green",IF(R10<10,"Amber","Red")) -> Green | T10: =IF(N10="Settled","None",IF(C10-Config!$B$1<=0,"Overdue",IF(C10-Config!$B$1<=1,"Critical",IF(C10-Config!$B$1<=3,"High","Low")))) -> None | U10: =IF(R10=0,"",RANK(R10,$R$5:$R$104,0))
A11: TRD-007 | B11: 45671 | C11: 45672 | D11: Fixed Income | E11: Tata Steel Corp Bond | F11: INE081A08123 | G11: INR | H11: 1000 | I11: 100.5 | J11: =H11*I11 -> 100500 | K11: Sharekhan | L11: ICICI Securities | M11: S7 Settlement | N11: Settled | P11: =Config!$B$1-B11 -> 510 | Q11: =IFERROR(INDEX('Failure Reference'!$C$4:$C$9,MATCH(O11,'Failure Reference'!$A$4:$A$9,0)),0) -> 0 | R11: =IF(N11="Settled",0,Q11+P11*0.5+IFERROR(INDEX(Config!$B$4:$B$7,MATCH(D11,Config!$A$4:$A$7,0)),1)+IF(C11-Config!$B$1<=1,5,0)) -> 0 | S11: =IF(R11=0,"Green",IF(R11<10,"Amber","Red")) -> Green | T11: =IF(N11="Settled","None",IF(C11-Config!$B$1<=0,"Overdue",IF(C11-Config!$B$1<=1,"Critical",IF(C11-Config!$B$1<=3,"High","Low")))) -> None | U11: =IF(R11=0,"",RANK(R11,$R$5:$R$104,0))
A12: TRD-008 | B12: 45721 | C12: 45722 | D12: Fixed Income | E12: 7.30% GOI 2053 | F12: IN002023Y456 | G12: INR | H12: 2000 | I12: 98.64 | J12: =H12*I12 -> 197280 | K12: Motilal Oswal | L12: IIFL Securities | M12: S7 Settlement | N12: Settled | P12: =Config!$B$1-B12 -> 460 | Q12: =IFERROR(INDEX('Failure Reference'!$C$4:$C$9,MATCH(O12,'Failure Reference'!$A$4:$A$9,0)),0) -> 0 | R12: =IF(N12="Settled",0,Q12+P12*0.5+IFERROR(INDEX(Config!$B$4:$B$7,MATCH(D12,Config!$A$4:$A$7,0)),1)+IF(C12-Config!$B$1<=1,5,0)) -> 0 | S12: =IF(R12=0,"Green",IF(R12<10,"Amber","Red")) -> Green | T12: =IF(N12="Settled","None",IF(C12-Config!$B$1<=0,"Overdue",IF(C12-Config!$B$1<=1,"Critical",IF(C12-Config!$B$1<=3,"High","Low")))) -> None | U12: =IF(R12=0,"",RANK(R12,$R$5:$R$104,0))
A13: TRD-009 | B13: 45704 | C13: 45705 | D13: Fixed Income | E13: 6.99% GOI 2026 | F13: IN002023Y789 | G13: INR | H13: 10000 | I13: 99.74 | J13: =H13*I13 -> 997400 | K13: ICICI Securities | L13: JM Financial | M13: S7 Settlement | N13: Settled | P13: =Config!$B$1-B13 -> 477 | Q13: =IFERROR(INDEX('Failure Reference'!$C$4:$C$9,MATCH(O13,'Failure Reference'!$A$4:$A$9,0)),0) -> 0 | R13: =IF(N13="Settled",0,Q13+P13*0.5+IFERROR(INDEX(Config!$B$4:$B$7,MATCH(D13,Config!$A$4:$A$7,0)),1)+IF(C13-Config!$B$1<=1,5,0)) -> 0 | S13: =IF(R13=0,"Green",IF(R13<10,"Amber","Red")) -> Green | T13: =IF(N13="Settled","None",IF(C13-Config!$B$1<=0,"Overdue",IF(C13-Config!$B$1<=1,"Critical",IF(C13-Config!$B$1<=3,"High","Low")))) -> None | U13: =IF(R13=0,"",RANK(R13,$R$5:$R$104,0))
A14: TRD-010 | B14: 45798 | C14: 45799 | D14: Commodities | E14: Gold Futures (MCX) | F14: N/A | G14: INR | H14: 10 | I14: 74044.27 | J14: =H14*I14 -> 740442.7 | K14: ICICI Securities | L14: Axis Securities | M14: S1 Validation | N14: In Progress | P14: =Config!$B$1-B14 -> 383 | Q14: =IFERROR(INDEX('Failure Reference'!$C$4:$C$9,MATCH(O14,'Failure Reference'!$A$4:$A$9,0)),0) -> 0 | R14: =IF(N14="Settled",0,Q14+P14*0.5+IFERROR(INDEX(Config!$B$4:$B$7,MATCH(D14,Config!$A$4:$A$7,0)),1)+IF(C14-Config!$B$1<=1,5,0)) -> 199 | S14: =IF(R14=0,"Green",IF(R14<10,"Amber","Red")) -> Red | T14: =IF(N14="Settled","None",IF(C14-Config!$B$1<=0,"Overdue",IF(C14-Config!$B$1<=1,"Critical",IF(C14-Config!$B$1<=3,"High","Low")))) -> Overdue | U14: =IF(R14=0,"",RANK(R14,$R$5:$R$104,0)) -> 22
A15: TRD-011 | B15: 45762 | C15: 45763 | D15: Equity | E15: ITC Ltd | F15: INE154A01025 | G15: INR | H15: 500 | I15: 417.69 | J15: =H15*I15 -> 208845 | K15: Angel One | L15: HDFC Securities | M15: S7 Settlement | N15: Settled | P15: =Config!$B$1-B15 -> 419 | Q15: =IFERROR(INDEX('Failure Reference'!$C$4:$C$9,MATCH(O15,'Failure Reference'!$A$4:$A$9,0)),0) -> 0 | R15: =IF(N15="Settled",0,Q15+P15*0.5+IFERROR(INDEX(Config!$B$4:$B$7,MATCH(D15,Config!$A$4:$A$7,0)),1)+IF(C15-Config!$B$1<=1,5,0)) -> 0 | S15: =IF(R15=0,"Green",IF(R15<10,"Amber","Red")) -> Green | T15: =IF(N15="Settled","None",IF(C15-Config!$B$1<=0,"Overdue",IF(C15-Config!$B$1<=1,"Critical",IF(C15-Config!$B$1<=3,"High","Low")))) -> None | U15: =IF(R15=0,"",RANK(R15,$R$5:$R$104,0))
A16: TRD-012 | B16: 45700 | C16: 45701 | D16: Commodities | E16: Natural Gas Futures (MCX) | F16: N/A | G16: USD | H16: 10 | I16: 3.04 | J16: =H16*I16 -> 30.4 | K16: IIFL Securities | L16: Axis Securities | M16: S7 Settlement | N16: Settled | P16: =Config!$B$1-B16 -> 481 | Q16: =IFERROR(INDEX('Failure Reference'!$C$4:$C$9,MATCH(O16,'Failure Reference'!$A$4:$A$9,0)),0) -> 0 | R16: =IF(N16="Settled",0,Q16+P16*0.5+IFERROR(INDEX(Config!$B$4:$B$7,MATCH(D16,Config!$A$4:$A$7,0)),1)+IF(C16-Config!$B$1<=1,5,0)) -> 0 | S16: =IF(R16=0,"Green",IF(R16<10,"Amber","Red")) -> Green | T16: =IF(N16="Settled","None",IF(C16-Config!$B$1<=0,"Overdue",IF(C16-Config!$B$1<=1,"Critical",IF(C16-Config!$B$1<=3,"High","Low")))) -> None | U16: =IF(R16=0,"",RANK(R16,$R$5:$R$104,0))
A17: TRD-013 | B17: 45766 | C17: 45767 | D17: Fixed Income | E17: Tata Steel Corp Bond | F17: INE081A08123 | G17: INR | H17: 25000 | I17: 102.96 | J17: =H17*I17 -> 2574000 | K17: IIFL Securities | L17: Motilal Oswal | M17: S7 Settlement | N17: Settled | P17: =Config!$B$1-B17 -> 415 | Q17: =IFERROR(INDEX('Failure Reference'!$C$4:$C$9,MATCH(O17,'Failure Reference'!$A$4:$A$9,0)),0) -> 0 | R17: =IF(N17="Settled",0,Q17+P17*0.5+IFERROR(INDEX(Config!$B$4:$B$7,MATCH(D17,Config!$A$4:$A$7,0)),1)+IF(C17-Config!$B$1<=1,5,0)) -> 0 | S17: =IF(R17=0,"Green",IF(R17<10,"Amber","Red")) -> Green | T17: =IF(N17="Settled","None",IF(C17-Config!$B$1<=0,"Overdue",IF(C17-Config!$B$1<=1,"Critical",IF(C17-Config!$B$1<=3,"High","Low")))) -> None | U17: =IF(R17=0,"",RANK(R17,$R$5:$R$104,0))
A18: TRD-014 | B18: 45706 | C18: 45707 | D18: Equity | E18: ICICI Bank Ltd | F18: INE090A01021 | G18: INR | H18: 200 | I18: 1172.5 | J18: =H18*I18 -> 234500 | K18: Nuvama Wealth | L18: JM Financial | M18: S7 Settlement | N18: Settled | P18: =Config!$B$1-B18 -> 475 | Q18: =IFERROR(INDEX('Failure Reference'!$C$4:$C$9,MATCH(O18,'Failure Reference'!$A$4:$A$9,0)),0) -> 0 | R18: =IF(N18="Settled",0,Q18+P18*0.5+IFERROR(INDEX(Config!$B$4:$B$7,MATCH(D18,Config!$A$4:$A$7,0)),1)+IF(C18-Config!$B$1<=1,5,0)) -> 0 | S18: =IF(R18=0,"Green",IF(R18<10,"Amber","Red")) -> Green | T18: =IF(N18="Settled","None",IF(C18-Config!$B$1<=0,"Overdue",IF(C18-Config!$B$1<=1,"Critical",IF(C18-Config!$B$1<=3,"High","Low")))) -> None | U18: =IF(R18=0,"",RANK(R18,$R$5:$R$104,0))
A19: TRD-015 | B19: 45673 | C19: 45674 | D19: Equity | E19: Maruti Suzuki | F19: INE585B01010 | G19: INR | H19: 300 | I19: 10751.81 | J19: =H19*I19 -> 3225543 | K19: Nuvama Wealth | L19: IIFL Securities | M19: S7 Settlement | N19: Settled | P19: =Config!$B$1-B19 -> 508 | Q19: =IFERROR(INDEX('Failure Reference'!$C$4:$C$9,MATCH(O19,'Failure Reference'!$A$4:$A$9,0)),0) -> 0 | R19: =IF(N19="Settled",0,Q19+P19*0.5+IFERROR(INDEX(Config!$B$4:$B$7,MATCH(D19,Config!$A$4:$A$7,0)),1)+IF(C19-Config!$B$1<=1,5,0)) -> 0 | S19: =IF(R19=0,"Green",IF(R19<10,"Amber","Red")) -> Green | T19: =IF(N19="Settled","None",IF(C19-Config!$B$1<=0,"Overdue",IF(C19-Config!$B$1<=1,"Critical",IF(C19-Config!$B$1<=3,"High","Low")))) -> None | U19: =IF(R19=0,"",RANK(R19,$R$5:$R$104,0))
... A21: TRD-017 | B21: 45705 | C21: 45706 | D21: Equity | E21: Infosys Ltd | F21: INE009A01021 | G21: INR | H21: 750 | I21: 1454.33 | J21: =H21*I21 -> 1090747.5 | K21: Kotak Securities | L21: IIFL Securities | M21: S7 Settlement | N21: Settled | P21: =Config!$B$1-B21 -> 476 | Q21: =IFERROR(INDEX('Failure Reference'!$C$4:$C$9,MATCH(O21,'Failure Reference'!$A$4:$A$9,0)),0) -> 0 | R21: =IF(N21="Settled",0,Q21+P21*0.5+IFERROR(INDEX(Config!$B$4:$B$7,MATCH(D21,Config!$A$4:$A$7,0)),1)+IF(C21-Config!$B$1<=1,5,0)) -> 0 | S21: =IF(R21=0,"Green",IF(R21<10,"Amber","Red")) -> Green | T21: =IF(N21="Settled","None",IF(C21-Config!$B$1<=0,"Overdue",IF(C21-Config!$B$1<=1,"Critical",IF(C21-Config!$B$1<=3,"High","Low")))) -> None | U21: =IF(R21=0,"",RANK(R21,$R$5:$R$104,0))
A22: TRD-018 | B22: 45688 | C22: 45689 | D22: Equity | E22: Sun Pharma | F22: INE044A01036 | G22: INR | H22: 750 | I22: 1344.98 | J22: =H22*I22 -> 1008735 | K22: Nuvama Wealth | L22: HDFC Securities | M22: S5 Matching | N22: Break | O22: Matching Break | P22: =Config!$B$1-B22 -> 493 | Q22: =IFERROR(INDEX('Failure Reference'!$C$4:$C$9,MATCH(O22,'Failure Reference'!$A$4:$A$9,0)),0) -> 8 | R22: =IF(N22="Settled",0,Q22+P22*0.5+IFERROR(INDEX(Config!$B$4:$B$7,MATCH(D22,Config!$A$4:$A$7,0)),1)+IF(C22-Config!$B$1<=1,5,0)) -> 260.5 | S22: =IF(R22=0,"Green",IF(R22<10,"Amber","Red")) -> Red | T22: =IF(N22="Settled","None",IF(C22-Config!$B$1<=0,"Overdue",IF(C22-Config!$B$1<=1,"Critical",IF(C22-Config!$B$1<=3,"High","Low")))) -> Overdue | U22: =IF(R22=0,"",RANK(R22,$R$5:$R$104,0)) -> 4
A23: TRD-019 | B23: 45816 | C23: 45817 | D23: Equity | E23: Infosys Ltd | F23: INE009A01021 | G23: INR | H23: 500 | I23: 1543.92 | J23: =H23*I23 -> 771960 | K23: Nuvama Wealth | L23: JM Financial | M23: S2 Enrichment | N23: In Progress | P23: =Config!$B$1-B23 -> 365 | Q23: =IFERROR(INDEX('Failure Reference'!$C$4:$C$9,MATCH(O23,'Failure Reference'!$A$4:$A$9,0)),0) -> 0 | R23: =IF(N23="Settled",0,Q23+P23*0.5+IFERROR(INDEX(Config!$B$4:$B$7,MATCH(D23,Config!$A$4:$A$7,0)),1)+IF(C23-Config!$B$1<=1,5,0)) -> 188.5 | S23: =IF(R23=0,"Green",IF(R23<10,"Amber","Red")) -> Red | T23: =IF(N23="Settled","None",IF(C23-Config!$B$1<=0,"Overdue",IF(C23-Config!$B$1<=1,"Critical",IF(C23-Config!$B$1<=3,"High","Low")))) -> Overdue | U23: =IF(R23=0,"",RANK(R23,$R$5:$R$104,0)) -> 25
A24: TRD-020 | B24: 45724 | C24: 45725 | D24: Fixed Income | E24: 7.30% GOI 2053 | F24: IN002023Y456 | G24: INR | H24: 5000 | I24: 97.47 | J24: =H24*I24 -> 487350 | K24: Angel One | L24: Motilal Oswal | M24: S7 Settlement | N24: Settled | P24: =Config!$B$1-B24 -> 457 | Q24: =IFERROR(INDEX('Failure Reference'!$C$4:$C$9,MATCH(O24,'Failure Reference'!$A$4:$A$9,0)),0) -> 0 | R24: =IF(N24="Settled",0,Q24+P24*0.5+IFERROR(INDEX(Config!$B$4:$B$7,MATCH(D24,Config!$A$4:$A$7,0)),1)+IF(C24-Config!$B$1<=1,5,0)) -> 0 | S24: =IF(R24=0,"Green",IF(R24<10,"Amber","Red")) -> Green | T24: =IF(N24="Settled","None",IF(C24-Config!$B$1<=0,"Overdue",IF(C24-Config!$B$1<=1,"Critical",IF(C24-Config!$B$1<=3,"High","Low")))) -> None | U24: =IF(R24=0,"",RANK(R24,$R$5:$R$104,0))
A25: TRD-021 | B25: 45829 | C25: 45830 | D25: Equity | E25: Bajaj Finance Ltd | F25: INE296A01024 | G25: INR | H25: 300 | I25: 7094.52 | J25: =H25*I25 -> 2128356 | K25: ICICI Securities | L25: HDFC Securities | M25: S7 Settlement | N25: Settled | P25: =Config!$B$1-B25 -> 352 | Q25: =IFERROR(INDEX('Failure Reference'!$C$4:$C$9,MATCH(O25,'Failure Reference'!$A$4:$A$9,0)),0) -> 0 | R25: =IF(N25="Settled",0,Q25+P25*0.5+IFERROR(INDEX(Config!$B$4:$B$7,MATCH(D25,Config!$A$4:$A$7,0)),1)+IF(C25-Config!$B$1<=1,5,0)) -> 0 | S25: =IF(R25=0,"Green",IF(R25<10,"Amber","Red")) -> Green | T25: =IF(N25="Settled","None",IF(C25-Config!$B$1<=0,"Overdue",IF(C25-Config!$B$1<=1,"Critical",IF(C25-Config!$B$1<=3,"High","Low")))) -> None | U25: =IF(R25=0,"",RANK(R25,$R$5:$R$104,0))
A26: TRD-022 | B26: 45775 | C26: 45776 | D26: Commodities | E26: Copper Futures (MCX) | F26: N/A | G26: INR | H26: 200 | I26: 4.55 | J26: =H26*I26 -> 910 | K26: JM Financial | L26: Kotak Securities | M26: S7 Settlement | N26: Settled | P26: =Config!$B$1-B26 -> 406 | Q26: =IFERROR(INDEX('Failure Reference'!$C$4:$C$9,MATCH(O26,'Failure Reference'!$A$4:$A$9,0)),0) -> 0 | R26: =IF(N26="Settled",0,Q26+P26*0.5+IFERROR(INDEX(Config!$B$4:$B$7,MATCH(D26,Config!$A$4:$A$7,0)),1)+IF(C26-Config!$B$1<=1,5,0)) -> 0 | S26: =IF(R26=0,"Green",IF(R26<10,"Amber","Red")) -> Green | T26: =IF(N26="Settled","None",IF(C26-Config!$B$1<=0,"Overdue",IF(C26-Config!$B$1<=1,"Critical",IF(C26-Config!$B$1<=3,"High","Low")))) -> None | U26: =IF(R26=0,"",RANK(R26,$R$5:$R$104,0))
A27: TRD-023 | B27: 45787 | C27: 45788 | D27: Equity | E27: ICICI Bank Ltd | F27: INE090A01021 | G27: INR | H27: 200 | I27: 1168.53 | J27: =H27*I27 -> 233706 | K27: ICICI Securities | L27: Axis Securities | M27: S7 Settlement | N27: Settled | P27: =Config!$B$1-B27 -> 394 | Q27: =IFERROR(INDEX('Failure Reference'!$C$4:$C$9,MATCH(O27,'Failure Reference'!$A$4:$A$9,0)),0) -> 0 | R27: =IF(N27="Settled",0,Q27+P27*0.5+IFERROR(INDEX(Config!$B$4:$B$7,MATCH(D27,Config!$A$4:$A$7,0)),1)+IF(C27-Config!$B$1<=1,5,0)) -> 0 | S27: =IF(R27=0,"Green",IF(R27<10,"Amber","Red")) -> Green | T27: =IF(N27="Settled","None",IF(C27-Config!$B$1<=0,"Overdue",IF(C27-Config!$B$1<=1,"Critical",IF(C27-Config!$B$1<=3,"High","Low")))) -> None | U27: =IF(R27=0,"",RANK(R27,$R$5:$R$104,0))
A28: TRD-024 | B28: 45752 | C28: 45753 | D28: Equity | E28: ICICI Bank Ltd | F28: INE090A01021 | G28: INR | H28: 200 | I28: 1113.08 | J28: =H28*I28 -> 222616 | K28: JM Financial | L28: Axis Securities | M28: S5 Matching | N28: Break | O28: Matching Break | P28: =Config!$B$1-B28 -> 429 | Q28: =IFERROR(INDEX('Failure Reference'!$C$4:$C$9,MATCH(O28,'Failure Reference'!$A$4:$A$9,0)),0) -> 8 | R28: =IF(N28="Settled",0,Q28+P28*0.5+IFERROR(INDEX(Config!$B$4:$B$7,MATCH(D28,Config!$A$4:$A$7,0)),1)+IF(C28-Config!$B$1<=1,5,0)) -> 228.5 | S28: =IF(R28=0,"Green",IF(R28<10,"Amber","Red")) -> Red | T28: =IF(N28="Settled","None",IF(C28-Config!$B$1<=0,"Overdue",IF(C28-Config!$B$1<=1,"Critical",IF(C28-Config!$B$1<=3,"High","Low")))) -> Overdue | U28: =IF(R28=0,"",RANK(R28,$R$5:$R$104,0)) -> 16
A29: TRD-025 | B29: 45814 | C29: 45815 | D29: Derivatives | E29: EURINR Futures | F29: N/A | G29: INR | H29: 1 | I29: 91.16 | J29: =H29*I29 -> 91.16 | K29: JM Financial | L29: Axis Securities | M29: S5 Matching | N29: In Progress | P29: =Config!$B$1-B29 -> 367 | Q29: =IFERROR(INDEX('Failure Reference'!$C$4:$C$9,MATCH(O29,'Failure Reference'!$A$4:$A$9,0)),0) -> 0 | R29: =IF(N29="Settled",0,Q29+P29*0.5+IFERROR(INDEX(Config!$B$4:$B$7,MATCH(D29,Config!$A$4:$A$7,0)),1)+IF(C29-Config!$B$1<=1,5,0)) -> 190.5 | S29: =IF(R29=0,"Green",IF(R29<10,"Amber","Red")) -> Red | T29: =IF(N29="Settled","None",IF(C29-Config!$B$1<=0,"Overdue",IF(C29-Config!$B$1<=1,"Critical",IF(C29-Config!$B$1<=3,"High","Low")))) -> Overdue | U29: =IF(R29=0,"",RANK(R29,$R$5:$R$104,0)) -> 24
A30: TRD-026 | B30: 45684 | C30: 45685 | D30: Equity | E30: Sun Pharma | F30: INE044A01036 | G30: INR | H30: 200 | I30: 1347.5 | J30: =H30*I30 -> 269500 | K30: ICICI Securities | L30: Nuvama Wealth | M30: S7 Settlement | N30: Settled | P30: =Config!$B$1-B30 -> 497 | Q30: =IFERROR(INDEX('Failure Reference'!$C$4:$C$9,MATCH(O30,'Failure Reference'!$A$4:$A$9,0)),0) -> 0 | R30: =IF(N30="Settled",0,Q30+P30*0.5+IFERROR(INDEX(Config!$B$4:$B$7,MATCH(D30,Config!$A$4:$A$7,0)),1)+IF(C30-Config!$B$1<=1,5,0)) -> 0 | S30: =IF(R30=0,"Green",IF(R30<10,"Amber","Red")) -> Green | T30: =IF(N30="Settled","None",IF(C30-Config!$B$1<=0,"Overdue",IF(C30-Config!$B$1<=1,"Critical",IF(C30-Config!$B$1<=3,"High","Low")))) -> None | U30: =IF(R30=0,"",RANK(R30,$R$5:$R$104,0))
A31: TRD-027 | B31: 45697 | C31: 45698 | D31: Equity | E31: ICICI Bank Ltd | F31: INE090A01021 | G31: INR | H31: 300 | I31: 1131.74 | J31: =H31*I31 -> 339522 | K31: Sharekhan | L31: Kotak Securities | M31: S5 Matching | N31: In Progress | P31: =Config!$B$1-B31 -> 484 | Q31: =IFERROR(INDEX('Failure Reference'!$C$4:$C$9,MATCH(O31,'Failure Reference'!$A$4:$A$9,0)),0) -> 0 | R31: =IF(N31="Settled",0,Q31+P31*0.5+IFERROR(INDEX(Config!$B$4:$B$7,MATCH(D31,Config!$A$4:$A$7,0)),1)+IF(C31-Config!$B$1<=1,5,0)) -> 248 | S31: =IF(R31=0,"Green",IF(R31<10,"Amber","Red")) -> Red | T31: =IF(N31="Settled","None",IF(C31-Config!$B$1<=0,"Overdue",IF(C31-Config!$B$1<=1,"Critical",IF(C31-Config!$B$1<=3,"High","Low")))) -> Overdue | U31: =IF(R31=0,"",RANK(R31,$R$5:$R$104,0)) -> 10
A32: TRD-028 | B32: 45820 | C32: 45821 | D32: Equity | E32: Wipro Ltd | F32: INE075A01022 | G32: INR | H32: 300 | I32: 475.26 | J32: =H32*I32 -> 142578 | K32: Axis Securities | L32: HDFC Securities | M32: S7 Settlement | N32: Settled | P32: =Config!$B$1-B32 -> 361 | Q32: =IFERROR(INDEX('Failure Reference'!$C$4:$C$9,MATCH(O32,'Failure Reference'!$A$4:$A$9,0)),0) -> 0 | R32: =IF(N32="Settled",0,Q32+P32*0.5+IFERROR(INDEX(Config!$B$4:$B$7,MATCH(D32,Config!$A$4:$A$7,0)),1)+IF(C32-Config!$B$1<=1,5,0)) -> 0 | S32: =IF(R32=0,"Green",IF(R32<10,"Amber","Red")) -> Green | T32: =IF(N32="Settled","None",IF(C32-Config!$B$1<=0,"Overdue",IF(C32-Config!$B$1<=1,"Critical",IF(C32-Config!$B$1<=3,"High","Low")))) -> None | U32: =IF(R32=0,"",RANK(R32,$R$5:$R$104,0))
A33: TRD-029 | B33: 45681 | C33: 45682 | D33: Commodities | E33: Natural Gas Futures (MCX) | F33: N/A | G33: USD | H33: 50 | I33: 2.67 | J33: =H33*I33 -> 133.5 | K33: Motilal Oswal | L33: Sharekhan | M33: S1 Validation | N33: In Progress | P33: =Config!$B$1-B33 -> 500 | Q33: =IFERROR(INDEX('Failure Reference'!$C$4:$C$9,MATCH(O33,'Failure Reference'!$A$4:$A$9,0)),0) -> 0 | R33: =IF(N33="Settled",0,Q33+P33*0.5+IFERROR(INDEX(Config!$B$4:$B$7,MATCH(D33,Config!$A$4:$A$7,0)),1)+IF(C33-Config!$B$1<=1,5,0)) -> 257.5 | S33: =IF(R33=0,"Green",IF(R33<10,"Amber","Red")) -> Red | T33: =IF(N33="Settled","None",IF(C33-Config!$B$1<=0,"Overdue",IF(C33-Config!$B$1<=1,"Critical",IF(C33-Config!$B$1<=3,"High","Low")))) -> Overdue | U33: =IF(R33=0,"",RANK(R33,$R$5:$R$104,0)) -> 6
A34: TRD-030 | B34: 45771 | C34: 45772 | D34: Fixed Income | E34: T-Bill 182D | F34: IN002024T002 | G34: INR | H34: 10000 | I34: 99.04 | J34: =H34*I34 -> 990400 | K34: ICICI Securities | L34: Motilal Oswal | M34: S7 Settlement | N34: Settled | P34: =Config!$B$1-B34 -> 410 | Q34: =IFERROR(INDEX('Failure Reference'!$C$4:$C$9,MATCH(O34,'Failure Reference'!$A$4:$A$9,0)),0) -> 0 | R34: =IF(N34="Settled",0,Q34+P34*0.5+IFERROR(INDEX(Config!$B$4:$B$7,MATCH(D34,Config!$A$4:$A$7,0)),1)+IF(C34-Config!$B$1<=1,5,0)) -> 0 | S34: =IF(R34=0,"Green",IF(R34<10,"Amber","Red")) -> Green | T34: =IF(N34="Settled","None",IF(C34-Config!$B$1<=0,"Overdue",IF(C34-Config!$B$1<=1,"Critical",IF(C34-Config!$B$1<=3,"High","Low")))) -> None | U34: =IF(R34=0,"",RANK(R34,$R$5:$R$104,0))
A35: TRD-031 | B35: 45834 | C35: 45835 | D35: Equity | E35: Sun Pharma | F35: INE044A01036 | G35: INR | H35: 200 | I35: 1386.29 | J35: =H35*I35 -> 277258 | K35: Sharekhan | L35: Nuvama Wealth | M35: S7 Settlement | N35: Settled | P35: =Config!$B$1-B35 -> 347 | Q35: =IFERROR(INDEX('Failure Reference'!$C$4:$C$9,MATCH(O35,'Failure Reference'!$A$4:$A$9,0)),0) -> 0 | R35: =IF(N35="Settled",0,Q35+P35*0.5+IFERROR(INDEX(Config!$B$4:$B$7,MATCH(D35,Config!$A$4:$A$7,0)),1)+IF(C35-Config!$B$1<=1,5,0)) -> 0 | S35: =IF(R35=0,"Green",IF(R35<10,"Amber","Red")) -> Green | T35: =IF(N35="Settled","None",IF(C35-Config!$B$1<=0,"Overdue",IF(C35-Config!$B$1<=1,"Critical",IF(C35-Config!$B$1<=3,"High","Low")))) -> None | U35: =IF(R35=0,"",RANK(R35,$R$5:$R$104,0))
A36: TRD-032 | B36: 45695 | C36: 45696 | D36: Equity | E36: Larsen & Toubro | F36: INE018A01030 | G36: INR | H36: 200 | I36: 3101.09 | J36: =H36*I36 -> 620218 | K36: Sharekhan | L36: HDFC Securities | M36: S7 Settlement | N36: Settled | P36: =Config!$B$1-B36 -> 486 | Q36: =IFERROR(INDEX('Failure Reference'!$C$4:$C$9,MATCH(O36,'Failure Reference'!$A$4:$A$9,0)),0) -> 0 | R36: =IF(N36="Settled",0,Q36+P36*0.5+IFERROR(INDEX(Config!$B$4:$B$7,MATCH(D36,Config!$A$4:$A$7,0)),1)+IF(C36-Config!$B$1<=1,5,0)) -> 0 | S36: =IF(R36=0,"Green",IF(R36<10,"Amber","Red")) -> Green | T36: =IF(N36="Settled","None",IF(C36-Config!$B$1<=0,"Overdue",IF(C36-Config!$B$1<=1,"Critical",IF(C36-Config!$B$1<=3,"High","Low")))) -> None | U36: =IF(R36=0,"",RANK(R36,$R$5:$R$104,0))
A37: TRD-033 | B37: 45749 | C37: 45750 | D37: Derivatives | E37: Bank Nifty Futures | F37: N/A | G37: INR | H37: 50 | I37: 47475.64 | J37: =H37*I37 -> 2373782 | K37: ICICI Securities | L37: Angel One | M37: S7 Settlement | N37: Settled | P37: =Config!$B$1-B37 -> 432 | Q37: =IFERROR(INDEX('Failure Reference'!$C$4:$C$9,MATCH(O37,'Failure Reference'!$A$4:$A$9,0)),0) -> 0 | R37: =IF(N37="Settled",0,Q37+P37*0.5+IFERROR(INDEX(Config!$B$4:$B$7,MATCH(D37,Config!$A$4:$A$7,0)),1)+IF(C37-Config!$B$1<=1,5,0)) -> 0 | S37: =IF(R37=0,"Green",IF(R37<10,"Amber","Red")) -> Green | T37: =IF(N37="Settled","None",IF(C37-Config!$B$1<=0,"Overdue",IF(C37-Config!$B$1<=1,"Critical",IF(C37-Config!$B$1<=3,"High","Low")))) -> None | U37: =IF(R37=0,"",RANK(R37,$R$5:$R$104,0))
A38: TRD-034 | B38: 45801 | C38: 45802 | D38: Derivatives | E38: USDINR Futures | F38: N/A | G38: INR | H38: 20 | I38: 84.75 | J38: =H38*I38 -> 1695 | K38: Kotak Securities | L38: Motilal Oswal | M38: S7 Settlement | N38: Settled | P38: =Config!$B$1-B38 -> 380 | Q38: =IFERROR(INDEX('Failure Reference'!$C$4:$C$9,MATCH(O38,'Failure Reference'!$A$4:$A$9,0)),0) -> 0 | R38: =IF(N38="Settled",0,Q38+P38*0.5+IFERROR(INDEX(Config!$B$4:$B$7,MATCH(D38,Config!$A$4:$A$7,0)),1)+IF(C38-Config!$B$1<=1,5,0)) -> 0 | S38: =IF(R38=0,"Green",IF(R38<10,"Amber","Red")) -> Green | T38: =IF(N38="Settled","None",IF(C38-Config!$B$1<=0,"Overdue",IF(C38-Config!$B$1<=1,"Critical",IF(C38-Config!$B$1<=3,"High","Low")))) -> None | U38: =IF(R38=0,"",RANK(R38,$R$5:$R$104,0))
A39: TRD-035 | B39: 45703 | C39: 45704 | D39: Equity | E39: Sun Pharma | F39: INE044A01036 | G39: INR | H39: 500 | I39: 1314.42 | J39: =H39*I39 -> 657210 | K39: Sharekhan | L39: IIFL Securities | M39: S7 Settlement | N39: Settled | P39: =Config!$B$1-B39 -> 478 | Q39: =IFERROR(INDEX('Failure Reference'!$C$4:$C$9,MATCH(O39,'Failure Reference'!$A$4:$A$9,0)),0) -> 0 | R39: =IF(N39="Settled",0,Q39+P39*0.5+IFERROR(INDEX(Config!$B$4:$B$7,MATCH(D39,Config!$A$4:$A$7,0)),1)+IF(C39-Config!$B$1<=1,5,0)) -> 0 | S39: =IF(R39=0,"Green",IF(R39<10,"Amber","Red")) -> Green | T39: =IF(N39="Settled","None",IF(C39-Config!$B$1<=0,"Overdue",IF(C39-Config!$B$1<=1,"Critical",IF(C39-Config!$B$1<=3,"High","Low")))) -> None | U39: =IF(R39=0,"",RANK(R39,$R$5:$R$104,0))
A40: TRD-036 | B40: 45829 | C40: 45830 | D40: Derivatives | E40: Bank Nifty Futures | F40: N/A | G40: INR | H40: 5 | I40: 47214.4 | J40: =H40*I40 -> 236072 | K40: ICICI Securities | L40: IIFL Securities | M40: S7 Settlement | N40: Settled | P40: =Config!$B$1-B40 -> 352 | Q40: =IFERROR(INDEX('Failure Reference'!$C$4:$C$9,MATCH(O40,'Failure Reference'!$A$4:$A$9,0)),0) -> 0 | R40: =IF(N40="Settled",0,Q40+P40*0.5+IFERROR(INDEX(Config!$B$4:$B$7,MATCH(D40,Config!$A$4:$A$7,0)),1)+IF(C40-Config!$B$1<=1,5,0)) -> 0 | S40: =IF(R40=0,"Green",IF(R40<10,"Amber","Red")) -> Green | T40: =IF(N40="Settled","None",IF(C40-Config!$B$1<=0,"Overdue",IF(C40-Config!$B$1<=1,"Critical",IF(C40-Config!$B$1<=3,"High","Low")))) -> None | U40: =IF(R40=0,"",RANK(R40,$R$5:$R$104,0))
A41: TRD-037 | B41: 45667 | C41: 45668 | D41: Commodities | E41: Natural Gas Futures (MCX) | F41: N/A | G41: USD | H41: 25 | I41: 2.73 | J41: =H41*I41 -> 68.25 | K41: Sharekhan | L41: Axis Securities | M41: S7 Settlement | N41: Break | O41: Settlement Fail | P41: =Config!$B$1-B41 -> 514 | Q41: =IFERROR(INDEX('Failure Reference'!$C$4:$C$9,MATCH(O41,'Failure Reference'!$A$4:$A$9,0)),0) -> 10 | R41: =IF(N41="Settled",0,Q41+P41*0.5+IFERROR(INDEX(Config!$B$4:$B$7,MATCH(D41,Config!$A$4:$A$7,0)),1)+IF(C41-Config!$B$1<=1,5,0)) -> 274.5 | S41: =IF(R41=0,"Green",IF(R41<10,"Amber","Red")) -> Red | T41: =IF(N41="Settled","None",IF(C41-Config!$B$1<=0,"Overdue",IF(C41-Config!$B$1<=1,"Critical",IF(C41-Config!$B$1<=3,"High","Low")))) -> Overdue | U41: =IF(R41=0,"",RANK(R41,$R$5:$R$104,0)) -> 1
A42: TRD-038 | B42: 45716 | C42: 45717 | D42: Derivatives | E42: Bank Nifty Futures | F42: N/A | G42: INR | H42: 1 | I42: 48662.82 | J42: =H42*I42 -> 48662.82 | K42: Angel One | L42: Sharekhan | M42: S7 Settlement | N42: Settled | P42: =Config!$B$1-B42 -> 465 | Q42: =IFERROR(INDEX('Failure Reference'!$C$4:$C$9,MATCH(O42,'Failure Reference'!$A$4:$A$9,0)),0) -> 0 | R42: =IF(N42="Settled",0,Q42+P42*0.5+IFERROR(INDEX(Config!$B$4:$B$7,MATCH(D42,Config!$A$4:$A$7,0)),1)+IF(C42-Config!$B$1<=1,5,0)) -> 0 | S42: =IF(R42=0,"Green",IF(R42<10,"Amber","Red")) -> Green | T42: =IF(N42="Settled","None",IF(C42-Config!$B$1<=0,"Overdue",IF(C42-Config!$B$1<=1,"Critical",IF(C42-Config!$B$1<=3,"High","Low")))) -> None | U42: =IF(R42=0,"",RANK(R42,$R$5:$R$104,0))
...

Sheet Config
A1: Reference Date | B1: =TODAY() -> 46181
A3: Asset Class | B3: Risk Weight
A4: Equity | B4: 1
A5: Fixed Income | B5: 1.5
A6: Derivatives | B6: 2
A7: Commodities | B7: 2.5

Sheet Stage Reference Guide
A1: TRADE LIFECYCLE — STAGE REFERENCE GUIDE
A3: Stage | B3: Stage Name | C3: Description | D3: Operational Purpose | E3: Responsible Team | F3: Systems Used | G3: Failure Points | H3: STP Check
A4: S0 | B4: Trade Capture | C4: Trade details entered / auto-booked into OMS; Trade ID generated | D4: Ensure all execution data is captured accurately in front-office systems | E4: Front Office / Trade Support | F4: Bloomberg AIM, Charles River, FlexTrade | G4: Duplicate booking, wrong quantity, wrong account, missing trade time | H4: STP from execution feed via FIX
A5: S1 | B5: Validation | C5: System validates ISIN, LEI, SSI, counterparty static data | D5: Prevent invalid or stale reference data from progressing through lifecycle | E5: Middle Office / Data Management | F5: Bloomberg Reference Data, In-house Security Master | G5: Invalid ISIN, missing LEI, stale SSI, unknown counterparty | H5: Auto-reject on validation failure
A6: S2 | B6: Enrichment | C6: Trade enriched with settlement details, custodian SSI, accrued interest (FI) | D6: Add all settlement-critical data required for downstream processing | E6: Middle Office / Settlement | F6: Static Data Systems, Broadridge, In-house Middleware | G6: Missing SSI, unknown custodian, enrichment timeout, incorrect accrued interest | H6: Auto-enrichment if SSI found in master
A7: S3 | B7: Confirmation | C7: Trade confirmation sent to counterparty; affirmation requested | D7: Establish bilateral agreement on trade economics before matching | E7: Middle Office / Confirmations | F7: Omgeo CTM, Markit Wire, SWIFT MT300 | G7: Late confirmation, unconfirmed trade, wrong counterparty contact | H7: Auto-confirm if electronic matching enabled
A8: S4 | B8: Allocation | C8: Block trade split across funds/accounts; allocation confirmed to prime broker | D8: Ensure correct fund/account attribution for NAV and regulatory reporting | E8: Middle Office / Allocations | F8: OMS, SWIFT MT515, Omgeo CTM | G8: Late allocation, allocation sum ≠ block qty, wrong fund code | H8: Auto-allocate if rules configured in OMS
A9: S5 | B9: Matching | C9: Both counterparties compare and affirm trade details on CTM/DTCC | D9: Achieve affirmed status required for clearing eligibility | E9: Middle Office / Matching | F9: Omgeo CTM, Markit Wire, DTCC TradeSuite | G9: Price/qty mismatch, late affirmation, wrong side, unmatched after cut-off | H9: Auto-match if all details align exactly
A10: S6 | B10: Settlement Instruction | C10: CCP novates; net obligations calculated; initial margin posted | D10: Prepare final settlement instructions for depository/RTGS transmission | E10: Back Office / Clearing | F10: NSCCL, CCIL, DTCC, LCH, SWIFT MT540-543 | G10: Margin shortfall, CCP rejection, netting failure, wrong instruction type | H10: Auto-clear on CCP acceptance
A11: S7 | B11: Settlement | C11: DVP exchange of cash & securities via depository / RTGS | D11: Final exchange of assets; trade completes lifecycle | E11: Back Office / Settlement | F11: NSDL, CDSL, RTGS, SWIFT MT541/543 | G11: Short delivery, funding failure, depot mismatch, late DVP | H11: STP via SWIFT if SSI and cash position correct

Sheet Failure Reference
A1: OPERATIONAL FAILURE SCENARIOS — BREAK MANAGEMENT REFERENCE
A3: Failure Type | B3: Description | C3: Severity Score | D3: Resolution Steps | E3: Risk Level
A4: Matching Break | B4: Price or quantity mismatch between counterparties on affirmation platform; trade remains unmatched | C4: 8 | D4: 1. Identify discrepancy on CTM 2. Call broker middle office 3. Agree correct economics 4. Amend and re-submit affirmation | E4: HIGH
A5: Settlement Fail | B5: DVP fails on settlement date due to insufficient securities or cash at custodian | C5: 10 | D5: 1. Contact CP treasury/custodian immediately 2. Assess short extension possibility 3. Move to fail status if unresolved 4. Calculate interest claim and notify client | E5: CRITICAL
A6: Allocation Error | B6: Block trade allocation sum does not equal block quantity or wrong fund attribution | C6: 7 | D6: 1. Pull original block from OMS 2. Verify allocation percentages 3. Re-allocate correctly 4. Re-submit to prime broker | E6: HIGH
A7: SSI Error | B7: Settlement Standing Instruction missing or incorrect for counterparty/currency/depository | C7: 6 | D7: 1. Contact broker for correct SSI 2. Load SSI into static data 3. Re-run enrichment 4. Escalate if settlement date approaching | E7: MEDIUM
A8: Trade Capture Error | B8: Wrong instrument, quantity, price, or direction captured at booking stage | C8: 5 | D8: 1. Identify error via validation rules 2. Cancel incorrect trade 3. Re-book with correct details 4. Notify trader and compliance | E8: MEDIUM
A9: Corporate Action Impact | B9: Stock split, bonus, or rights issue creates position reconciliation break post-settlement | C9: 4 | D9: 1. Pull corporate action record from depository 2. Manually adjust OMS position 3. Pass journal entry 4. Update recon system (TLM/Intellimatch) | E9: LOW

Sheet Broker Scorecard
A1: BROKER PERFORMANCE SCORECARD
A2: Metrics derived from Trade Database | Rolling T+1 Settlement Analysis
A4: Rank | B4: Broker | C4: Total Trades | D4: Settled Trades | E4: Open Breaks | F4: Break Rate % | G4: Avg Aging (Days) | H4: Settlement Success % | I4: STP Rate % | J4: Performance Score
A5: =RANK(J5,$J$5:$J$14,0) -> 2 | B5: HDFC Securities | C5: =COUNTIF('Trade Database'!$K$5:$K$104,B5) -> 11 | D5: =COUNTIFS('Trade Database'!$K$5:$K$104,B5,'Trade Database'!$N$5:$N$104,"Settled") -> 9 | E5: =COUNTIFS('Trade Database'!$K$5:$K$104,B5,'Trade Database'!$N$5:$N$104,"Break") -> 0 | F5: =IF(C5=0,0,E5/C5) -> 0 | G5: =AVERAGEIFS('Trade Database'!$P$5:$P$104,'Trade Database'!$K$5:$K$104,B5,'Trade Database'!$N$5:$N$104,"<>Settled") -> 441 | H5: =IF(C5=0,0,D5/C5) -> 0.81818182 | I5: =IF(C5=0,0,D5/C5) -> 0.81818182 | J5: =H5*0.5+I5*0.3+(1-F5)*0.2 -> 0.85454545
A6: =RANK(J6,$J$5:$J$14,0) -> 1 | B6: ICICI Securities | C6: =COUNTIF('Trade Database'!$K$5:$K$104,B6) -> 12 | D6: =COUNTIFS('Trade Database'!$K$5:$K$104,B6,'Trade Database'!$N$5:$N$104,"Settled") -> 11 | E6: =COUNTIFS('Trade Database'!$K$5:$K$104,B6,'Trade Database'!$N$5:$N$104,"Break") -> 0 | F6: =IF(C6=0,0,E6/C6) -> 0 | G6: =AVERAGEIFS('Trade Database'!$P$5:$P$104,'Trade Database'!$K$5:$K$104,B6,'Trade Database'!$N$5:$N$104,"<>Settled") -> 383 | H6: =IF(C6=0,0,D6/C6) -> 0.91666667 | I6: =IF(C6=0,0,D6/C6) -> 0.91666667 | J6: =H6*0.5+I6*0.3+(1-F6)*0.2 -> 0.93333333
A7: =RANK(J7,$J$5:$J$14,0) -> 10 | B7: Motilal Oswal | C7: =COUNTIF('Trade Database'!$K$5:$K$104,B7) -> 7 | D7: =COUNTIFS('Trade Database'!$K$5:$K$104,B7,'Trade Database'!$N$5:$N$104,"Settled") -> 3 | E7: =COUNTIFS('Trade Database'!$K$5:$K$104,B7,'Trade Database'!$N$5:$N$104,"Break") -> 1 | F7: =IF(C7=0,0,E7/C7) -> 0.14285714 | G7: =AVERAGEIFS('Trade Database'!$P$5:$P$104,'Trade Database'!$K$5:$K$104,B7,'Trade Database'!$N$5:$N$104,"<>Settled") -> 472.75 | H7: =IF(C7=0,0,D7/C7) -> 0.42857143 | I7: =IF(C7=0,0,D7/C7) -> 0.42857143 | J7: =H7*0.5+I7*0.3+(1-F7)*0.2 -> 0.51428571
A8: =RANK(J8,$J$5:$J$14,0) -> 3 | B8: Kotak Securities | C8: =COUNTIF('Trade Database'!$K$5:$K$104,B8) -> 10 | D8: =COUNTIFS('Trade Database'!$K$5:$K$104,B8,'Trade Database'!$N$5:$N$104,"Settled") -> 8 | E8: =COUNTIFS('Trade Database'!$K$5:$K$104,B8,'Trade Database'!$N$5:$N$104,"Break") -> 1 | F8: =IF(C8=0,0,E8/C8) -> 0.1 | G8: =AVERAGEIFS('Trade Database'!$P$5:$P$104,'Trade Database'!$K$5:$K$104,B8,'Trade Database'!$N$5:$N$104,"<>Settled") -> 473.5 | H8: =IF(C8=0,0,D8/C8) -> 0.8 | I8: =IF(C8=0,0,D8/C8) -> 0.8 | J8: =H8*0.5+I8*0.3+(1-F8)*0.2 -> 0.82
A9: =RANK(J9,$J$5:$J$14,0) -> 6 | B9: Axis Securities | C9: =COUNTIF('Trade Database'!$K$5:$K$104,B9) -> 8 | D9: =COUNTIFS('Trade Database'!$K$5:$K$104,B9,'Trade Database'!$N$5:$N$104,"Settled") -> 6 | E9: =COUNTIFS('Trade Database'!$K$5:$K$104,B9,'Trade Database'!$N$5:$N$104,"Break") -> 1 | F9: =IF(C9=0,0,E9/C9) -> 0.125 | G9: =AVERAGEIFS('Trade Database'!$P$5:$P$104,'Trade Database'!$K$5:$K$104,B9,'Trade Database'!$N$5:$N$104,"<>Settled") -> 418 | H9: =IF(C9=0,0,D9/C9) -> 0.75 | I9: =IF(C9=0,0,D9/C9) -> 0.75 | J9: =H9*0.5+I9*0.3+(1-F9)*0.2 -> 0.775
A10: =RANK(J10,$J$5:$J$14,0) -> 6 | B10: Sharekhan | C10: =COUNTIF('Trade Database'!$K$5:$K$104,B10) -> 8 | D10: =COUNTIFS('Trade Database'!$K$5:$K$104,B10,'Trade Database'!$N$5:$N$104,"Settled") -> 6 | E10: =COUNTIFS('Trade Database'!$K$5:$K$104,B10,'Trade Database'!$N$5:$N$104,"Break") -> 1 | F10: =IF(C10=0,0,E10/C10) -> 0.125 | G10: =AVERAGEIFS('Trade Database'!$P$5:$P$104,'Trade Database'!$K$5:$K$104,B10,'Trade Database'!$N$5:$N$104,"<>Settled") -> 499 | H10: =IF(C10=0,0,D10/C10) -> 0.75 | I10: =IF(C10=0,0,D10/C10) -> 0.75 | J10: =H10*0.5+I10*0.3+(1-F10)*0.2 -> 0.775
A11: =RANK(J11,$J$5:$J$14,0) -> 5 | B11: Angel One | C11: =COUNTIF('Trade Database'!$K$5:$K$104,B11) -> 12 | D11: =COUNTIFS('Trade Database'!$K$5:$K$104,B11,'Trade Database'!$N$5:$N$104,"Settled") -> 9 | E11: =COUNTIFS('Trade Database'!$K$5:$K$104,B11,'Trade Database'!$N$5:$N$104,"Break") -> 1 | F11: =IF(C11=0,0,E11/C11) -> 0.083333333 | G11: =AVERAGEIFS('Trade Database'!$P$5:$P$104,'Trade Database'!$K$5:$K$104,B11,'Trade Database'!$N$5:$N$104,"<>Settled") -> 439.33333 | H11: =IF(C11=0,0,D11/C11) -> 0.75 | I11: =IF(C11=0,0,D11/C11) -> 0.75 | J11: =H11*0.5+I11*0.3+(1-F11)*0.2 -> 0.78333333
A12: =RANK(J12,$J$5:$J$14,0) -> 4 | B12: IIFL Securities | C12: =COUNTIF('Trade Database'!$K$5:$K$104,B12) -> 11 | D12: =COUNTIFS('Trade Database'!$K$5:$K$104,B12,'Trade Database'!$N$5:$N$104,"Settled") -> 9 | E12: =COUNTIFS('Trade Database'!$K$5:$K$104,B12,'Trade Database'!$N$5:$N$104,"Break") -> 2 | F12: =IF(C12=0,0,E12/C12) -> 0.18181818 | G12: =AVERAGEIFS('Trade Database'!$P$5:$P$104,'Trade Database'!$K$5:$K$104,B12,'Trade Database'!$N$5:$N$104,"<>Settled") -> 457.5 | H12: =IF(C12=0,0,D12/C12) -> 0.81818182 | I12: =IF(C12=0,0,D12/C12) -> 0.81818182 | J12: =H12*0.5+I12*0.3+(1-F12)*0.2 -> 0.81818182
A13: =RANK(J13,$J$5:$J$14,0) -> 9 | B13: JM Financial | C13: =COUNTIF('Trade Database'!$K$5:$K$104,B13) -> 10 | D13: =COUNTIFS('Trade Database'!$K$5:$K$104,B13,'Trade Database'!$N$5:$N$104,"Settled") -> 6 | E13: =COUNTIFS('Trade Database'!$K$5:$K$104,B13,'Trade Database'!$N$5:$N$104,"Break") -> 1 | F13: =IF(C13=0,0,E13/C13) -> 0.1 | G13: =AVERAGEIFS('Trade Database'!$P$5:$P$104,'Trade Database'!$K$5:$K$104,B13,'Trade Database'!$N$5:$N$104,"<>Settled") -> 434.75 | H13: =IF(C13=0,0,D13/C13) -> 0.6 | I13: =IF(C13=0,0,D13/C13) -> 0.6 | J13: =H13*0.5+I13*0.3+(1-F13)*0.2 -> 0.66
A14: =RANK(J14,$J$5:$J$14,0) -> 8 | B14: Nuvama Wealth | C14: =COUNTIF('Trade Database'!$K$5:$K$104,B14) -> 11 | D14: =COUNTIFS('Trade Database'!$K$5:$K$104,B14,'Trade Database'!$N$5:$N$104,"Settled") -> 8 | E14: =COUNTIFS('Trade Database'!$K$5:$K$104,B14,'Trade Database'!$N$5:$N$104,"Break") -> 2 | F14: =IF(C14=0,0,E14/C14) -> 0.18181818 | G14: =AVERAGEIFS('Trade Database'!$P$5:$P$104,'Trade Database'!$K$5:$K$104,B14,'Trade Database'!$N$5:$N$104,"<>Settled") -> 436 | H14: =IF(C14=0,0,D14/C14) -> 0.72727273 | I14: =IF(C14=0,0,D14/C14) -> 0.72727273 | J14: =H14*0.5+I14*0.3+(1-F14)*0.2 -> 0.74545455

Sheet Break Management Center
A1: BREAK MANAGEMENT CENTER
A2: Real-time break analysis by dimension | Heatmap intensity = break concentration
A4: BREAKS BY BROKER | G4: BREAKS BY ASSET CLASS
A5: Broker | B5: Break Count | C5: Total Value (₹) | D5: Avg Severity | G5: Asset Class | H5: Break Count | I5: Total Value (₹) | J5: Avg Severity
A6: HDFC Securities | B6: =COUNTIFS('Trade Database'!$K$5:$K$104,A6,'Trade Database'!$N$5:$N$104,"Break") -> 0 | C6: =SUMIFS('Trade Database'!$J$5:$J$104,'Trade Database'!$K$5:$K$104,A6,'Trade Database'!$N$5:$N$104,"Break") -> 0 | D6: =IFERROR(AVERAGEIFS('Trade Database'!$Q$5:$Q$104,'Trade Database'!$K$5:$K$104,A6,'Trade Database'!$N$5:$N$104,"Break"),0) -> 0 | G6: Equity | H6: =COUNTIFS('Trade Database'!$D$5:$D$104,G6,'Trade Database'!$N$5:$N$104,"Break") -> 4 | I6: =SUMIFS('Trade Database'!$J$5:$J$104,'Trade Database'!$D$5:$D$104,G6,'Trade Database'!$N$5:$N$104,"Break") -> 5453831 | J6: =IFERROR(AVERAGEIFS('Trade Database'!$Q$5:$Q$104,'Trade Database'!$D$5:$D$104,G6,'Trade Database'!$N$5:$N$104,"Break"),0) -> 7
A7: ICICI Securities | B7: =COUNTIFS('Trade Database'!$K$5:$K$104,A7,'Trade Database'!$N$5:$N$104,"Break") -> 0 | C7: =SUMIFS('Trade Database'!$J$5:$J$104,'Trade Database'!$K$5:$K$104,A7,'Trade Database'!$N$5:$N$104,"Break") -> 0 | D7: =IFERROR(AVERAGEIFS('Trade Database'!$Q$5:$Q$104,'Trade Database'!$K$5:$K$104,A7,'Trade Database'!$N$5:$N$104,"Break"),0) -> 0 | G7: Fixed Income | H7: =COUNTIFS('Trade Database'!$D$5:$D$104,G7,'Trade Database'!$N$5:$N$104,"Break") -> 3 | I7: =SUMIFS('Trade Database'!$J$5:$J$104,'Trade Database'!$D$5:$D$104,G7,'Trade Database'!$N$5:$N$104,"Break") -> 2502850 | J7: =IFERROR(AVERAGEIFS('Trade Database'!$Q$5:$Q$104,'Trade Database'!$D$5:$D$104,G7,'Trade Database'!$N$5:$N$104,"Break"),0) -> 6.3333333
A8: Motilal Oswal | B8: =COUNTIFS('Trade Database'!$K$5:$K$104,A8,'Trade Database'!$N$5:$N$104,"Break") -> 1 | C8: =SUMIFS('Trade Database'!$J$5:$J$104,'Trade Database'!$K$5:$K$104,A8,'Trade Database'!$N$5:$N$104,"Break") -> 2891.53 | D8: =IFERROR(AVERAGEIFS('Trade Database'!$Q$5:$Q$104,'Trade Database'!$K$5:$K$104,A8,'Trade Database'!$N$5:$N$104,"Break"),0) -> 10 | G8: Derivatives | H8: =COUNTIFS('Trade Database'!$D$5:$D$104,G8,'Trade Database'!$N$5:$N$104,"Break") -> 2 | I8: =SUMIFS('Trade Database'!$J$5:$J$104,'Trade Database'!$D$5:$D$104,G8,'Trade Database'!$N$5:$N$104,"Break") -> 3071.91 | J8: =IFERROR(AVERAGEIFS('Trade Database'!$Q$5:$Q$104,'Trade Database'!$D$5:$D$104,G8,'Trade Database'!$N$5:$N$104,"Break"),0) -> 8
A9: Kotak Securities | B9: =COUNTIFS('Trade Database'!$K$5:$K$104,A9,'Trade Database'!$N$5:$N$104,"Break") -> 1 | C9: =SUMIFS('Trade Database'!$J$5:$J$104,'Trade Database'!$K$5:$K$104,A9,'Trade Database'!$N$5:$N$104,"Break") -> 497550 | D9: =IFERROR(AVERAGEIFS('Trade Database'!$Q$5:$Q$104,'Trade Database'!$K$5:$K$104,A9,'Trade Database'!$N$5:$N$104,"Break"),0) -> 8 | G9: Commodities | H9: =COUNTIFS('Trade Database'!$D$5:$D$104,G9,'Trade Database'!$N$5:$N$104,"Break") -> 1 | I9: =SUMIFS('Trade Database'!$J$5:$J$104,'Trade Database'!$D$5:$D$104,G9,'Trade Database'!$N$5:$N$104,"Break") -> 68.25 | J9: =IFERROR(AVERAGEIFS('Trade Database'!$Q$5:$Q$104,'Trade Database'!$D$5:$D$104,G9,'Trade Database'!$N$5:$N$104,"Break"),0) -> 10
A10: Axis Securities | B10: =COUNTIFS('Trade Database'!$K$5:$K$104,A10,'Trade Database'!$N$5:$N$104,"Break") -> 1 | C10: =SUMIFS('Trade Database'!$J$5:$J$104,'Trade Database'!$K$5:$K$104,A10,'Trade Database'!$N$5:$N$104,"Break") -> 180.38 | D10: =IFERROR(AVERAGEIFS('Trade Database'!$Q$5:$Q$104,'Trade Database'!$K$5:$K$104,A10,'Trade Database'!$N$5:$N$104,"Break"),0) -> 6
A11: Sharekhan | B11: =COUNTIFS('Trade Database'!$K$5:$K$104,A11,'Trade Database'!$N$5:$N$104,"Break") -> 1 | C11: =SUMIFS('Trade Database'!$J$5:$J$104,'Trade Database'!$K$5:$K$104,A11,'Trade Database'!$N$5:$N$104,"Break") -> 68.25 | D11: =IFERROR(AVERAGEIFS('Trade Database'!$Q$5:$Q$104,'Trade Database'!$K$5:$K$104,A11,'Trade Database'!$N$5:$N$104,"Break"),0) -> 10
A12: BREAKS BY FAILURE TYPE | B12: =COUNTIFS('Trade Database'!$K$5:$K$104,A12,'Trade Database'!$N$5:$N$104,"Break") -> 0 | C12: =SUMIFS('Trade Database'!$J$5:$J$104,'Trade Database'!$K$5:$K$104,A12,'Trade Database'!$N$5:$N$104,"Break") -> 0 | D12: =IFERROR(AVERAGEIFS('Trade Database'!$Q$5:$Q$104,'Trade Database'!$K$5:$K$104,A12,'Trade Database'!$N$5:$N$104,"Break"),0) -> 0 | G12: BREAKS BY MONTH
A13: Failure Type | B13: Count | C13: Total Value (₹) | D13: % of Breaks | G13: Month | H13: Break Count | I13: Total Trades | J13: Break Rate %
A14: Matching Break | B14: =COUNTIF('Trade Database'!$O$5:$O$104,A14) -> 3 | C14: =SUMIF('Trade Database'!$O$5:$O$104,A14,'Trade Database'!$J$5:$J$104) -> 1728901 | D14: =IF($B$20=0,0,B14/$B$20) -> 0.3 | G14: Jan-2025 | H14: =SUMPRODUCT((TEXT('Trade Database'!$B$5:$B$104,"MMM-YYYY")=G14)*('Trade Database'!$N$5:$N$104="Break")) -> 4 | I14: =SUMPRODUCT((TEXT('Trade Database'!$B$5:$B$104,"MMM-YYYY")=G14)*1) -> 15 | J14: =IF(I14=0,0,H14/I14) -> 0.26666667
A15: Settlement Fail | B15: =COUNTIF('Trade Database'!$O$5:$O$104,A15) -> 2 | C15: =SUMIF('Trade Database'!$O$5:$O$104,A15,'Trade Database'!$J$5:$J$104) -> 2959.78 | D15: =IF($B$20=0,0,B15/$B$20) -> 0.2 | G15: Feb-2025 | H15: =SUMPRODUCT((TEXT('Trade Database'!$B$5:$B$104,"MMM-YYYY")=G15)*('Trade Database'!$N$5:$N$104="Break")) -> 1 | I15: =SUMPRODUCT((TEXT('Trade Database'!$B$5:$B$104,"MMM-YYYY")=G15)*1) -> 20 | J15: =IF(I15=0,0,H15/I15) -> 0.05
A16: Allocation Error | B16: =COUNTIF('Trade Database'!$O$5:$O$104,A16) -> 2 | C16: =SUMIF('Trade Database'!$O$5:$O$104,A16,'Trade Database'!$J$5:$J$104) -> 1786060 | D16: =IF($B$20=0,0,B16/$B$20) -> 0.2 | G16: Mar-2025 | H16: =SUMPRODUCT((TEXT('Trade Database'!$B$5:$B$104,"MMM-YYYY")=G16)*('Trade Database'!$N$5:$N$104="Break")) -> 2 | I16: =SUMPRODUCT((TEXT('Trade Database'!$B$5:$B$104,"MMM-YYYY")=G16)*1) -> 16 | J16: =IF(I16=0,0,H16/I16) -> 0.125
A17: SSI Error | B17: =COUNTIF('Trade Database'!$O$5:$O$104,A17) -> 1 | C17: =SUMIF('Trade Database'!$O$5:$O$104,A17,'Trade Database'!$J$5:$J$104) -> 180.38 | D17: =IF($B$20=0,0,B17/$B$20) -> 0.1 | G17: Apr-2025 | H17: =SUMPRODUCT((TEXT('Trade Database'!$B$5:$B$104,"MMM-YYYY")=G17)*('Trade Database'!$N$5:$N$104="Break")) -> 2 | I17: =SUMPRODUCT((TEXT('Trade Database'!$B$5:$B$104,"MMM-YYYY")=G17)*1) -> 18 | J17: =IF(I17=0,0,H17/I17) -> 0.11111111
A18: Trade Capture Error | B18: =COUNTIF('Trade Database'!$O$5:$O$104,A18) -> 1 | C18: =SUMIF('Trade Database'!$O$5:$O$104,A18,'Trade Database'!$J$5:$J$104) -> 3432720 | D18: =IF($B$20=0,0,B18/$B$20) -> 0.1 | G18: May-2025 | H18: =SUMPRODUCT((TEXT('Trade Database'!$B$5:$B$104,"MMM-YYYY")=G18)*('Trade Database'!$N$5:$N$104="Break")) -> 1 | I18: =SUMPRODUCT((TEXT('Trade Database'!$B$5:$B$104,"MMM-YYYY")=G18)*1) -> 14 | J18: =IF(I18=0,0,H18/I18) -> 0.071428571
A19: Corporate Action Impact | B19: =COUNTIF('Trade Database'!$O$5:$O$104,A19) -> 1 | C19: =SUMIF('Trade Database'!$O$5:$O$104,A19,'Trade Database'!$J$5:$J$104) -> 1009000 | D19: =IF($B$20=0,0,B19/$B$20) -> 0.1 | G19: Jun-2025 | H19: =SUMPRODUCT((TEXT('Trade Database'!$B$5:$B$104,"MMM-YYYY")=G19)*('Trade Database'!$N$5:$N$104="Break")) -> 0 | I19: =SUMPRODUCT((TEXT('Trade Database'!$B$5:$B$104,"MMM-YYYY")=G19)*1) -> 17 | J19: =IF(I19=0,0,H19/I19) -> 0
A20: TOTAL | B20: =SUM(B14:B19) -> 10 | C20: =SUM(C14:C19) -> 7959821.2 | D20: =SUM(D14:D19) -> 1

Sheet SLA Monitoring Center
A1: SLA MONITORING CENTER
A2: T+1 Settlement SLA Tracking | Green = Within SLA | Amber = Near Breach | Red = Breached
A4: SLA DEFINITIONS | G4: SLA METRICS
A5: Stage | B5: SLA Target | C5: Within SLA | D5: Near Breach | E5: Breached | G5: Metric | H5: Count | I5: Percentage | J5: Status
A6: S0 Trade Capture | B6: T+15 min | C6: Aging ≤ 0.5 days | D6: Aging 0.5-1 day | E6: Aging > 1 day | G6: Within SLA | H6: =COUNTIFS('Trade Database'!$N$5:$N$104,"Settled")+COUNTIFS('Trade Database'!$N$5:$N$104,"In Progress",'Trade Database'!$P$5:$P$104,"<=1") -> 75 | I6: =H6/100 -> 0.75 | J6: =IF(I6>=0.8,"GOOD","REVIEW") -> REVIEW
A7: S1 Validation | B7: T+30 min | C7: Aging ≤ 0.5 days | D7: Aging 0.5-1 day | E7: Aging > 1 day | G7: Near Breach | H7: =COUNTIFS('Trade Database'!$N$5:$N$104,"In Progress",'Trade Database'!$P$5:$P$104,">1",'Trade Database'!$P$5:$P$104,"<=2") -> 0 | I7: =H7/100 -> 0 | J7: =IF(I7<=0.15,"ACCEPTABLE","ELEVATED") -> ACCEPTABLE
A8: S2 Enrichment | B8: T+2 hours | C8: Aging ≤ 0.5 days | D8: Aging 0.5-1 day | E8: Aging > 1 day | G8: Breached | H8: =COUNTIFS('Trade Database'!$N$5:$N$104,"Break")+COUNTIFS('Trade Database'!$N$5:$N$104,"In Progress",'Trade Database'!$P$5:$P$104,">2") -> 25 | I8: =H8/100 -> 0.25 | J8: =IF(I8<=0.05,"GOOD","CRITICAL") -> CRITICAL
A9: S3 Confirmation | B9: T+4 hours | C9: Aging ≤ 0.5 days | D9: Aging 0.5-1 day | E9: Aging > 1 day | G9: Total Monitored | H9: =SUM(H6:H8) -> 100 | I9: =SUM(I6:I8) -> 1
A10: S4 Allocation | B10: T+6 hours | C10: Aging ≤ 0.5 days | D10: Aging 0.5-1 day | E10: Aging > 1 day
A11: S5 Matching | B11: End of Day T | C11: Aging ≤ 0.5 days | D11: Aging 0.5-1 day | E11: Aging > 1 day
A12: SLA STATUS BY LIFECYCLE STAGE | B12: T+1 09:00 | C12: Aging ≤ 1 day | D12: Aging 1-2 days | E12: Aging > 2 days
A13: Stage | B13: Total | C13: Within SLA | D13: Near Breach | E13: Breached
A14: S0 Trade Capture | B14: =COUNTIF('Trade Database'!$M$5:$M$104,A14) -> 5 | C14: =COUNTIFS('Trade Database'!$M$5:$M$104,A14,'Trade Database'!$P$5:$P$104,"<=1") -> 0 | D14: =COUNTIFS('Trade Database'!$M$5:$M$104,A14,'Trade Database'!$P$5:$P$104,">1",'Trade Database'!$P$5:$P$104,"<=2") -> 0 | E14: =COUNTIFS('Trade Database'!$M$5:$M$104,A14,'Trade Database'!$P$5:$P$104,">2") -> 5
A15: S1 Validation | B15: =COUNTIF('Trade Database'!$M$5:$M$104,A15) -> 3 | C15: =COUNTIFS('Trade Database'!$M$5:$M$104,A15,'Trade Database'!$P$5:$P$104,"<=1") -> 0 | D15: =COUNTIFS('Trade Database'!$M$5:$M$104,A15,'Trade Database'!$P$5:$P$104,">1",'Trade Database'!$P$5:$P$104,"<=2") -> 0 | E15: =COUNTIFS('Trade Database'!$M$5:$M$104,A15,'Trade Database'!$P$5:$P$104,">2") -> 3
A16: S2 Enrichment | B16: =COUNTIF('Trade Database'!$M$5:$M$104,A16) -> 2 | C16: =COUNTIFS('Trade Database'!$M$5:$M$104,A16,'Trade Database'!$P$5:$P$104,"<=1") -> 0 | D16: =COUNTIFS('Trade Database'!$M$5:$M$104,A16,'Trade Database'!$P$5:$P$104,">1",'Trade Database'!$P$5:$P$104,"<=2") -> 0 | E16: =COUNTIFS('Trade Database'!$M$5:$M$104,A16,'Trade Database'!$P$5:$P$104,">2") -> 2
A17: S3 Confirmation | B17: =COUNTIF('Trade Database'!$M$5:$M$104,A17) -> 1 | C17: =COUNTIFS('Trade Database'!$M$5:$M$104,A17,'Trade Database'!$P$5:$P$104,"<=1") -> 0 | D17: =COUNTIFS('Trade Database'!$M$5:$M$104,A17,'Trade Database'!$P$5:$P$104,">1",'Trade Database'!$P$5:$P$104,"<=2") -> 0 | E17: =COUNTIFS('Trade Database'!$M$5:$M$104,A17,'Trade Database'!$P$5:$P$104,">2") -> 1
A18: S4 Allocation | B18: =COUNTIF('Trade Database'!$M$5:$M$104,A18) -> 3 | C18: =COUNTIFS('Trade Database'!$M$5:$M$104,A18,'Trade Database'!$P$5:$P$104,"<=1") -> 0 | D18: =COUNTIFS('Trade Database'!$M$5:$M$104,A18,'Trade Database'!$P$5:$P$104,">1",'Trade Database'!$P$5:$P$104,"<=2") -> 0 | E18: =COUNTIFS('Trade Database'!$M$5:$M$104,A18,'Trade Database'!$P$5:$P$104,">2") -> 3
A19: S5 Matching | B19: =COUNTIF('Trade Database'!$M$5:$M$104,A19) -> 8 | C19: =COUNTIFS('Trade Database'!$M$5:$M$104,A19,'Trade Database'!$P$5:$P$104,"<=1") -> 0 | D19: =COUNTIFS('Trade Database'!$M$5:$M$104,A19,'Trade Database'!$P$5:$P$104,">1",'Trade Database'!$P$5:$P$104,"<=2") -> 0 | E19: =COUNTIFS('Trade Database'!$M$5:$M$104,A19,'Trade Database'!$P$5:$P$104,">2") -> 8
A20: S6 Settlement Instruction | B20: =COUNTIF('Trade Database'!$M$5:$M$104,A20) -> 0 | C20: =COUNTIFS('Trade Database'!$M$5:$M$104,A20,'Trade Database'!$P$5:$P$104,"<=1") -> 0 | D20: =COUNTIFS('Trade Database'!$M$5:$M$104,A20,'Trade Database'!$P$5:$P$104,">1",'Trade Database'!$P$5:$P$104,"<=2") -> 0 | E20: =COUNTIFS('Trade Database'!$M$5:$M$104,A20,'Trade Database'!$P$5:$P$104,">2") -> 0
A21: S7 Settlement | B21: =COUNTIF('Trade Database'!$M$5:$M$104,A21) -> 78 | C21: =COUNTIFS('Trade Database'!$M$5:$M$104,A21,'Trade Database'!$P$5:$P$104,"<=1") -> 0 | D21: =COUNTIFS('Trade Database'!$M$5:$M$104,A21,'Trade Database'!$P$5:$P$104,">1",'Trade Database'!$P$5:$P$104,"<=2") -> 0 | E21: =COUNTIFS('Trade Database'!$M$5:$M$104,A21,'Trade Database'!$P$5:$P$104,">2") -> 78

Sheet Executive Dashboard
A1: EXECUTIVE DASHBOARD
A2: Operations Command Center | Real-time Trade Lifecycle Analytics | L2: =Config!$B$1 -> 46181
A4: Total Trades | F4: Settled Trades | K4: Pending Trades | P4: Asset Class | Q4: Count | S4: Broker | T4: Count | V4: Failure Type | W4: Count | Y4: Month | Z4: Total | AA4: Settled | AC4: Month | AD4: Success %
A5: =COUNTA('Trade Database'!$A$5:$A$104) -> 100 | F5: =COUNTIF('Trade Database'!$N$5:$N$104,"Settled") -> 75 | K5: =COUNTIFS('Trade Database'!$N$5:$N$104,"<>Settled",'Trade Database'!$N$5:$N$104,"<>Break") -> 15 | P5: Equity | Q5: =COUNTIF('Trade Database'!$D$5:$D$104,P5) -> 40 | S5: HDFC Securities | T5: =COUNTIF('Trade Database'!$K$5:$K$104,S5) -> 11 | V5: Matching Break | W5: =COUNTIF('Trade Database'!$O$5:$O$104,V5) -> 3 | Y5: Jan | Z5: =SUMPRODUCT((MONTH('Trade Database'!$B$5:$B$104)=1)*1) -> 15 | AA5: =SUMPRODUCT((MONTH('Trade Database'!$B$5:$B$104)=1)*('Trade Database'!$N$5:$N$104="Settled")) -> 9 | AC5: Jan | AD5: =IF(AG5=0,0,AH5/AG5) -> 0
P6: Fixed Income | Q6: =COUNTIF('Trade Database'!$D$5:$D$104,P6) -> 25 | S6: ICICI Securities | T6: =COUNTIF('Trade Database'!$K$5:$K$104,S6) -> 12 | V6: Settlement Fail | W6: =COUNTIF('Trade Database'!$O$5:$O$104,V6) -> 2 | Y6: Feb | Z6: =SUMPRODUCT((MONTH('Trade Database'!$B$5:$B$104)=2)*1) -> 20 | AA6: =SUMPRODUCT((MONTH('Trade Database'!$B$5:$B$104)=2)*('Trade Database'!$N$5:$N$104="Settled")) -> 15 | AC6: Feb | AD6: =IF(AG6=0,0,AH6/AG6) -> 0
P7: Derivatives | Q7: =COUNTIF('Trade Database'!$D$5:$D$104,P7) -> 20 | S7: Motilal Oswal | T7: =COUNTIF('Trade Database'!$K$5:$K$104,S7) -> 7 | V7: Allocation Error | W7: =COUNTIF('Trade Database'!$O$5:$O$104,V7) -> 2 | Y7: Mar | Z7: =SUMPRODUCT((MONTH('Trade Database'!$B$5:$B$104)=3)*1) -> 16 | AA7: =SUMPRODUCT((MONTH('Trade Database'!$B$5:$B$104)=3)*('Trade Database'!$N$5:$N$104="Settled")) -> 11 | AC7: Mar | AD7: =IF(AG7=0,0,AH7/AG7) -> 0
P8: Commodities | Q8: =COUNTIF('Trade Database'!$D$5:$D$104,P8) -> 15 | S8: Kotak Securities | T8: =COUNTIF('Trade Database'!$K$5:$K$104,S8) -> 10 | V8: SSI Error | W8: =COUNTIF('Trade Database'!$O$5:$O$104,V8) -> 1 | Y8: Apr | Z8: =SUMPRODUCT((MONTH('Trade Database'!$B$5:$B$104)=4)*1) -> 18 | AA8: =SUMPRODUCT((MONTH('Trade Database'!$B$5:$B$104)=4)*('Trade Database'!$N$5:$N$104="Settled")) -> 14 | AC8: Apr | AD8: =IF(AG8=0,0,AH8/AG8) -> 0
A9: Open Breaks | F9: STP Rate | K9: Settlement Success | S9: Axis Securities | T9: =COUNTIF('Trade Database'!$K$5:$K$104,S9) -> 8 | V9: Trade Capture Error | W9: =COUNTIF('Trade Database'!$O$5:$O$104,V9) -> 1 | Y9: May | Z9: =SUMPRODUCT((MONTH('Trade Database'!$B$5:$B$104)=5)*1) -> 14 | AA9: =SUMPRODUCT((MONTH('Trade Database'!$B$5:$B$104)=5)*('Trade Database'!$N$5:$N$104="Settled")) -> 11 | AC9: May | AD9: =IF(AG9=0,0,AH9/AG9) -> 0
A10: =COUNTIF('Trade Database'!$N$5:$N$104,"Break") -> 10 | F10: =COUNTIF('Trade Database'!$N$5:$N$104,"Settled")/COUNTA('Trade Database'!$A$5:$A$104) -> 0.75 | K10: =COUNTIF('Trade Database'!$N$5:$N$104,"Settled")/COUNTA('Trade Database'!$A$5:$A$104) -> 0.75 | V10: Corporate Action Impact | W10: =COUNTIF('Trade Database'!$O$5:$O$104,V10) -> 1 | Y10: Jun | Z10: =SUMPRODUCT((MONTH('Trade Database'!$B$5:$B$104)=6)*1) -> 17 | AA10: =SUMPRODUCT((MONTH('Trade Database'!$B$5:$B$104)=6)*('Trade Database'!$N$5:$N$104="Settled")) -> 15 | AC10: Jun | AD10: =IF(AG10=0,0,AH10/AG10) -> 0
A14: Avg Aging | F14: High Risk Trades | K14: Ops Health Score
A15: =AVERAGE('Trade Database'!$P$5:$P$104) -> 433.75 | F15: =COUNTIF('Trade Database'!$S$5:$S$104,"Red") -> 25 | K15: =MAX(0,100-COUNTIF('Trade Database'!$N$5:$N$104,"Break")*10-COUNTIF('Trade Database'!$S$5:$S$104,"Red")*5-COUNTIFS('Trade Database'!$T$5:$T$104,"Overdue")*3) -> 0
A19: FILTER PANEL
A20: Broker | C20: Asset Class | E20: Status | G20: Failure Type
A21: [Select Broker] | C21: [Select Asset Class] | E21: [Select Status] | G21: [Select Failure Type]
